<?xml version="1.0" ?>
<robot name="turtlebot3_burger"
  xmlns:xacro="http://ros.org/wiki/xacro">
  <!-- <xacro:include filename="$(find turtlebot3_description)/urdf/common_properties.urdf"/> -->

  <xacro:arg name="namespace" default=""/>
  <xacro:property name="namespace" value="$(arg namespace)"/>
  <!-- <xacro:property name="mesh_path" value="package://homework3/meshes"/> -->
  <xacro:property name="mesh_path" value="file://$(find vision_demo)/meshes"/>
  <!-- <xacro:property name="mesh_path" value="file:///home/sean/ros2_course_ws_master/install/homework3/share/homework3/meshes"/> -->

  <!-- Init colour -->
  <material name="black">
      <color rgba="0.0 0.0 0.0 1.0"/>
  </material>

  <material name="dark">
    <color rgba="0.3 0.3 0.3 1.0"/>
  </material>

  <material name="light_black">
    <color rgba="0.4 0.4 0.4 1.0"/>
  </material>

  <material name="blue">
    <color rgba="0.0 0.0 0.8 1.0"/>
  </material>

  <material name="green">
    <color rgba="0.0 0.8 0.0 1.0"/>
  </material>

  <material name="grey">
    <color rgba="0.5 0.5 0.5 1.0"/>
  </material>

  <material name="orange">
    <color rgba="1.0 0.4235 0.0392 1.0"/>
  </material>

  <material name="brown">
    <color rgba="0.8706 0.8118 0.7647 1.0"/>
  </material>

  <material name="red">
    <color rgba="0.8 0.0 0.0 1.0"/>
  </material>

  <material name="white">
    <color rgba="1.0 1.0 1.0 1.0"/>
  </material>

  <link name="${namespace}base_footprint"/>

  <joint name="${namespace}base_joint" type="fixed">
    <parent link="${namespace}base_footprint"/>
    <child link="${namespace}base_link"/>
    <origin xyz="0.0 0.0 0.010" rpy="0 0 0"/>
  </joint>

  <link name="${namespace}base_link">
    <visual>
      <origin xyz="-0.032 0 0.0" rpy="0 0 0"/>
      <geometry>
        <mesh filename="${mesh_path}/bases/burger_base.stl" scale="0.001 0.001 0.001"/>      
      </geometry>
      <material name="light_black"/>
    </visual>

    <collision>
      <origin xyz="-0.032 0 0.070" rpy="0 0 0"/>
      <geometry>
        <box size="0.140 0.140 0.143"/>
      </geometry>
    </collision>

    <inertial>
      <origin xyz="0 0 0" rpy="0 0 0"/>
      <mass value="8.2573504e-01"/>
      <inertia ixx="2.2124416e-03" ixy="-1.2294101e-05" ixz="3.4938785e-05" iyy="2.1193702e-03" iyz="-5.0120904e-06" izz="2.0064271e-03" />
    </inertial>
  </link>

  <joint name="${namespace}wheel_left_joint" type="continuous">
    <parent link="${namespace}base_link"/>
    <child link="${namespace}wheel_left_link"/>
    <origin xyz="0.0 0.08 0.023" rpy="-1.57 0 0"/>
    <axis xyz="0 0 1"/>
  </joint>

  <link name="${namespace}wheel_left_link">
    <visual>
      <origin xyz="0 0 0" rpy="1.57 0 0"/>
      <geometry>
        <mesh filename="${mesh_path}/wheels/left_tire.stl" scale="0.001 0.001 0.001"/>
      </geometry>
      <material name="dark"/>
    </visual>

    <collision>
      <origin xyz="0 0 0" rpy="0 0 0"/>
      <geometry>
        <cylinder length="0.018" radius="0.033"/>
      </geometry>
    </collision>

    <inertial>
      <origin xyz="0 0 0" />
      <mass value="2.8498940e-02" />
      <inertia ixx="1.1175580e-05" ixy="-4.2369783e-11" ixz="-5.9381719e-09" iyy="1.1192413e-05" iyz="-1.4400107e-11" izz="2.0712558e-05" />
    </inertial>
  </link>

  <joint name="${namespace}wheel_right_joint" type="continuous">
    <parent link="${namespace}base_link"/>
    <child link="${namespace}wheel_right_link"/>
    <origin xyz="0.0 -0.080 0.023" rpy="-1.57 0 0"/>
    <axis xyz="0 0 1"/>
  </joint>

  <link name="${namespace}wheel_right_link">
    <visual>
      <origin xyz="0 0 0" rpy="1.57 0 0"/>
      <geometry>
        <mesh filename="${mesh_path}/wheels/right_tire.stl" scale="0.001 0.001 0.001"/>
      </geometry>
      <material name="dark"/>
    </visual>

    <collision>
      <origin xyz="0 0 0" rpy="0 0 0"/>
      <geometry>
        <cylinder length="0.018" radius="0.033"/>
      </geometry>
    </collision>

    <inertial>
      <origin xyz="0 0 0" />
      <mass value="2.8498940e-02" />
      <inertia ixx="1.1175580e-05" ixy="-4.2369783e-11" ixz="-5.9381719e-09" iyy="1.1192413e-05" iyz="-1.4400107e-11" izz="2.0712558e-05" />
    </inertial>
  </link>

  <joint name="${namespace}caster_back_joint" type="fixed">
    <parent link="${namespace}base_link"/>
    <child link="${namespace}caster_back_link"/>
    <origin xyz="-0.081 0 -0.004" rpy="-1.57 0 0"/>
  </joint>

  <link name="${namespace}caster_back_link">
    <collision>
      <origin xyz="0 0.001 0" rpy="0 0 0"/>
      <geometry>
        <box size="0.030 0.009 0.020"/>
      </geometry>
    </collision>

    <inertial>
      <origin xyz="0 0 0" />
      <mass value="0.005" />
      <inertia ixx="0.001" ixy="0.0" ixz="0.0" iyy="0.001" iyz="0.0" izz="0.001" />
    </inertial>
  </link>

  <joint name="${namespace}imu_joint" type="fixed">
    <parent link="${namespace}base_link"/>
    <child link="${namespace}imu_link"/>
    <origin xyz="-0.032 0 0.068" rpy="0 0 0"/>
  </joint>

  <link name="${namespace}imu_link"/>

  <joint name="${namespace}scan_joint" type="fixed">
    <parent link="${namespace}base_link"/>
    <child link="${namespace}base_scan"/>
    <origin xyz="-0.032 0 0.172" rpy="0 0 0"/>
  </joint>

  <link name="${namespace}base_scan">
    <visual>
      <origin xyz="0 0 0.0" rpy="0 0 0"/>
      <geometry>
        <mesh filename="${mesh_path}/sensors/lds.stl" scale="0.001 0.001 0.001"/>
      </geometry>
      <material name="dark"/>
    </visual>

    <collision>
      <origin xyz="0.015 0 -0.0065" rpy="0 0 0"/>
      <geometry>
        <cylinder length="0.0315" radius="0.055"/>
      </geometry>
    </collision>

    <inertial>
      <mass value="0.114" />
      <origin xyz="0 0 0" />
      <inertia ixx="0.001" ixy="0.0" ixz="0.0" iyy="0.001" iyz="0.0" izz="0.001" />
    </inertial>
  </link>

  <!-- ==================== CAMERA SENSOR ==================== -->
  <!-- Camera link - positioned at front-bottom of robot, angled down -->
  <joint name="${namespace}camera_joint" type="fixed">
    <parent link="${namespace}base_link"/>
    <child link="${namespace}camera_link"/>
    <!-- Position: front of robot (x=0.05), centered (y=0), low height (z=0.05) -->
    <!-- Orientation: tilted down 20 degrees (0.349 radians) to see ground markers -->
    <origin xyz="0.05 0 0.05" rpy="0 0 0"/>
  </joint>

  <link name="${namespace}camera_link">
    <visual>
      <origin xyz="0 0 0" rpy="0 0 0"/>
      <geometry>
        <box size="0.015 0.030 0.015"/>
      </geometry>
      <material name="red"/>
    </visual>

    <collision>
      <origin xyz="0 0 0" rpy="0 0 0"/>
      <geometry>
        <box size="0.015 0.030 0.015"/>
      </geometry>
    </collision>

    <inertial>
      <mass value="0.035"/>
      <origin xyz="0 0 0"/>
      <inertia ixx="0.001" ixy="0.0" ixz="0.0" 
               iyy="0.001" iyz="0.0" izz="0.001"/>
    </inertial>
  </link>

  <!-- Camera optical frame - follows ROS convention (x-right, y-down, z-forward) -->
  <joint name="${namespace}camera_optical_joint" type="fixed">
    <parent link="${namespace}camera_link"/>
    <child link="${namespace}camera_rgb_optical_frame"/>
    <!-- Rotate to ROS optical frame convention -->
    <origin xyz="0 0 0" rpy="-1.5707963267948966 0 -1.5707963267948966"/>
  </joint>

  <link name="${namespace}camera_rgb_optical_frame"/>

  <!-- ==================== GAZEBO CAMERA PLUGIN ==================== -->
  <gazebo reference="${namespace}camera_link">
    <material>Gazebo/Red</material>
    <sensor type="camera" name="camera_sensor">
      <update_rate>30.0</update_rate>
      <visualize>true</visualize>
      <camera name="camera">
        <horizontal_fov>1.0472</horizontal_fov> <!-- 60 degrees -->
        <image>
          <width>640</width>
          <height>480</height>
          <format>R8G8B8</format>
        </image>
        <clip>
          <near>0.02</near>
          <far>10</far>
        </clip>
        <noise>
          <type>gaussian</type>
          <mean>0.0</mean>
          <stddev>0.007</stddev>
        </noise>
      </camera>
      <plugin name="camera_controller" filename="libgazebo_ros_camera.so">
        <ros>
          <namespace>${namespace}</namespace>
          <remapping>~/image_raw:=camera/image_raw</remapping>
          <remapping>~/camera_info:=camera/camera_info</remapping>
        </ros>
        <camera_name>camera</camera_name>
        <frame_name>${namespace}camera_rgb_optical_frame</frame_name>
        <hack_baseline>0.07</hack_baseline>
      </plugin>
    </sensor>
  </gazebo>

  <!-- Gazebo plugin for diff drive in gazebo 11-->
  <gazebo> 
    <plugin name="gazebo_ros_control" filename="libgazebo_ros_diff_drive.so">
      <update_rate>30</update_rate>
      <left_joint>${namespace}wheel_left_joint</left_joint>
      <right_joint>${namespace}wheel_right_joint</right_joint>
      <wheel_separation>0.160</wheel_separation>
      <wheel_diameter>0.066</wheel_diameter>
      <max_wheel_torque>20</max_wheel_torque>
      <command_topic>cmd_vel</command_topic>
      <odometry_topic>odom</odometry_topic>
      <odometry_frame>odom</odometry_frame>
      <robot_base_frame>${namespace}base_footprint</robot_base_frame>
      <publish_odom>true</publish_odom>
      <publish_odom_tf>true</publish_odom_tf>
      <publish_wheel_tf>false</publish_wheel_tf>
    </plugin>
  </gazebo>

  <!-- Gazebo materials for visibility and plugins for lidar and joint state publisher-->
  <gazebo reference="${namespace}base_link">
    <material>Gazebo/DarkGrey</material>
    <visual>
      <material>
        <ambient>0.4 0.4 0.4 1</ambient>
        <diffuse>0.4 0.4 0.4 1</diffuse>
      </material>
    </visual>
  </gazebo>

  <gazebo reference="${namespace}wheel_left_link">
    <material>Gazebo/Black</material>
  </gazebo>

  <gazebo reference="${namespace}wheel_right_link">
    <material>Gazebo/Black</material>
  </gazebo>

  <gazebo reference="${namespace}caster_back_link">
    <material>Gazebo/Black</material>
    <visual>
      <material>
        <ambient>0.1 0.1 0.1 1</ambient>
        <diffuse>0.1 0.1 0.1 1</diffuse>
      </material>
    </visual>
    <mu1>0.0</mu1>
    <mu2>0.0</mu2>
  </gazebo>

  <gazebo reference="${namespace}base_scan">
    <material>Gazebo/Black</material>
    <sensor type="ray" name="lds_lfcd_sensor">
      <pose>0 0 0 0 0 0</pose>
      <visualize>false</visualize>
      <update_rate>5</update_rate>
      <ray>
        <scan>
          <horizontal>
            <samples>360</samples>
            <resolution>1</resolution>
            <min_angle>0.0</min_angle>
            <max_angle>6.28319</max_angle>
          </horizontal>
        </scan>
        <range>
          <min>0.120</min>
          <max>3.5</max>
          <resolution>0.015</resolution>
        </range>
        <noise>
          <type>gaussian</type>
          <mean>0.0</mean>
          <stddev>0.01</stddev>
        </noise>
      </ray>
      <plugin name="gazebo_ros_lds_lfcd_controller" filename="libgazebo_ros_ray_sensor.so">
        <ros>
          <remapping>~/out:=scan</remapping>
        </ros>
        <output_type>sensor_msgs/LaserScan</output_type>
        <frame_name>${namespace}base_scan</frame_name>
      </plugin>
    </sensor>
  </gazebo>

  <gazebo>
    <plugin name="gazebo_ros_joint_state_publisher" filename="libgazebo_ros_joint_state_publisher.so">
      <update_rate>20</update_rate>
      <joint_name>${namespace}wheel_left_joint</joint_name>
      <joint_name>${namespace}wheel_right_joint</joint_name>
    </plugin>
  </gazebo>

</robot>